Workbook

Sheet เงินคงเหลือประจำวัน
A1: ประเภท | B1: เงินสด | C1: เงินฝากธนาคาร | D1: เงินฝากส่วนราชการผู้เบิก | E1: รวม
A3: เงินงบประมาณ | B3: - | C3: - | D3: - | E3: -
A4: เงินรายได้แผ่นดิน | B4: - | C4: ='รับ-จ่าย'!AP3 -> 0 | D4: - | E4: =SUM(B4:D4) -> 0
A5: เงินนอกงบประมาณประเภท | B5: - | C5: - | D5: - | E5: -
A6: - เงินรายได้สถานศึกษา (เงินบริจาคธนาคารกรุงไทย) | B6: - | C6: ='รับ-จ่าย'!C3 -> 5221.27 | D6: - | E6: =SUM(B6:D6) -> 5221.27
A7: - เงินรายได้สถานศึกษา (เงินบริจาคธนาคาร ธ.ก.ส.) | B7: - | C7: ='รับ-จ่าย'!AV3 -> 74414.81 | D7: - | E7: =SUM(B7:D7) -> 74414.81
A8: - เงินรายได้สถานศึกษา (เงินค่าบำรุงลูกเสือ) | B8: - | C8: ='รับ-จ่าย'!F3 -> 1093.2 | D8: - | E8: =SUM(C8:D8) -> 1093.2
A9: - เงินค่าใช้จ่ายในการจัดการศึกษา (รายหัว) | B9: - | C9: ='รับ-จ่าย'!I3 -> 116168.12 | D9: - | E9: =SUM(B9:D9) -> 116168.12
A10: - (ค่าหนังสือเรียน) | B10: - | C10: ='รับ-จ่าย'!L3 -> 96558 | D10: - | E10: =SUM(B10:D10) -> 96558
A11: - (ค่าอุปกรณ์การเรียน) | B11: - | C11: ='รับ-จ่าย'!O3 -> 31410 | D11: - | E11: =SUM(B11:D11) -> 31410
A12: - (ค่าเครื่องแบบนักเรียน) | B12: - | C12: ='รับ-จ่าย'!R3 -> 58950 | D12: - | E12: =SUM(B12:D12) -> 58950
A13: - (ค่ากิจกรรมพัฒนาฯ) | B13: - | C13: ='รับ-จ่าย'!U3 -> 47375 | D13: - | E13: =SUM(B13:D13) -> 47375
A14: - เงินอุดหนุนปัจจัยพื้นฐานนักเรียนยากจน | B14: - | C14: ='รับ-จ่าย'!X3 -> 0 | D14: - | E14: =SUM(B14:D14) -> 0
A15: - เงินอุดหนุนโครงการอาหารกลางวัน | B15: - | C15: ='รับ-จ่าย'!AA3 -> 0 | D15: - | E15: =SUM(B15:D15) -> 0
A16: - เงินอุดหนุนนักเรียนยากจนพิเศษ (กสศ.) | B16: - | C16: ='รับ-จ่าย'!AD3 -> 99.87 | D16: - | E16: =SUM(B16:D16) -> 99.87
A17: - เงินประกันสัญญา | B17: - | C17: 0 | D17: ='รับ-จ่าย'!AG3 -> 13120 | E17: =SUM(B17:D17) -> 13120
A18: - เงินภาษีหัก ณ ที่ จ่าย | B18: ='รับ-จ่าย'!AJ3 -> 0 | C18: 0 | D18: - | E18: =SUM(B18:D18) -> 0
A21: รวม | B21: =SUM(B3:B19) -> 0 | C21: =SUM(C3:C20) -> 431290.27 | D21: =SUM(D3:D17) -> 13120 | E21: =SUM(B21:D21) -> 444410.27
A23: - บช. เงินรายได้แผ่นดิน | C23: =E4 -> 0
A24: - บช. (เงินรายได้สถานศึกษา)เงินบริจาค+ลูกเสือ | C24: =E6+E8 -> 6314.47 | D24: ดอกเบี้ย
A25: - บช. (เงินรายได้สถานศึกษา)เงินบริจาค ธกส | C25: =E7 -> 74414.81
A26: - บช. อุดหนุน (รายหัว) | C26: =SUM(E9:E14,E19:E20) -> 350461.12
A27: - บช. อาหารกลางวัน | C27: =E15 -> 0
A28: - บช. กสศ | C28: =E16 -> 99.87
B29: รวม | C29: =SUM(C23:C28) -> 431290.27
C31: ตามรายงาน | D31: ตามบัญชี | E31: ตรวจสอบ
A32: บัญชีเงินบริจาคเพื่อการศึกษากรุงไทย เลขบัญชี 661-1-80797-7 | C32: =C24 -> 6314.47 | D32: 6314.47 | E32: =C32-D32 -> 0
A33: บัญชีเงินบริจาคเพื่อการศึกษา ธกส เลขบัญชี 020249721560 | C33: =C25 -> 74414.81 | D33: 74414.81 | E33: =C33-D33 -> 0
A34: บัญชีเงินอุดหนุน เลขบัญชี 672-8-37706-9 | C34: =SUM(C26:D26) -> 350461.12 | D34: 350461.12 | E34: =C34-D34 -> 0
A35: บัญชีเงินอาหารกลางวัน เลขบัญชี 672-8-37707-7 | C35: =SUM(C27:D27) -> 0 | D35: 0 | E35: =C35-D35 -> 0
A36: บัญชี กศส.เพื่อโรงเรียนบ้านท่าชะอม เลขบัญชี 677-7-06005-7 | C36: =C28 -> 99.87 | D36: 99.87 | E36: =C36-D36 -> 2.6147973e-12
A37: เงินสด (เช็คธนาคาร) | C37: =B21 -> 0
C38: =SUM(C32:C37) -> 431290.27

Sheet รับ-จ่าย
A1: เงินบริจาค | B1: ยอดยกมา> | C1: 24858.02 | D1: เงินลูกเสือ | E1: ยอดยกมา> | F1: 1471.4 | G1: ค่าจัดการเรียนการสอน | H1: ยอดยกมา> | I1: 1720.97 | J1: หนังสือเรียน | K1: ยอดยกมา> | L1: 0 | M1: อุปกรณ์การเรียน | N1: ยอดยกมา> | O1: 0 | P1: เครื่องแบบนักเรียน | Q1: ยอดยกมา> | R1: 15200 | S1: พัฒนาผู้เรียน | T1: ยอดยกมา> | U1: 28330 | V1: พื้นฐานยากจน | W1: ยอดยกมา> | X1: 0 | Y1: อาหารกลางวัน | Z1: ยอดยกมา> | AA1: 46156 | AB1: กสศ | AC1: ยอดยกมา> | AD1: 87.07 | AE1: ประกันสัญญา | AF1: ยอดยกมา> | AG1: 13120 | AH1: ภาษีหัก ณ ที่จ่าย | AI1: ยอดยกมา> | AJ1: 0 | AK1: หลักประกันสุขภาพ อบต. | AL1: ยอดยกมา> | AM1: 0 | AN1: รายได้แผ่นดิน | AO1: ยอดยกมา> | AP1: 0 | AQ1: เงินโครงการลูกเสือสำรอง | AR1: ยอดยกมา> | AS1: 0 | AT1: เงินบริจาคธนาคาร ธกส | AU1: ยอดยกมา> | AV1: 0
A2: รับ | B2: จ่าย | C2: คงเหลือ | D2: รับ | E2: จ่าย | F2: คงเหลือ | G2: รับ | H2: จ่าย | I2: คงเหลือ | J2: รับ | K2: จ่าย | L2: คงเหลือ | M2: รับ | N2: จ่าย | O2: คงเหลือ | P2: รับ | Q2: จ่าย | R2: คงเหลือ | S2: รับ | T2: จ่าย | U2: คงเหลือ | V2: รับ | W2: จ่าย | X2: คงเหลือ | Y2: รับ | Z2: จ่าย | AA2: คงเหลือ | AB2: รับ | AC2: จ่าย | AD2: คงเหลือ | AE2: รับ | AF2: จ่าย | AG2: คงเหลือ | AH2: รับ | AI2: จ่าย | AJ2: คงเหลือ | AK2: รับ | AL2: จ่าย | AM2: คงเหลือ | AN2: รับ | AO2: จ่าย | AP2: คงเหลือ | AQ2: รับ | AR2: จ่าย | AS2: คงเหลือ | AT2: รับ | AU2: จ่าย | AV2: คงเหลือ
C3: =C1+A79-B79 -> 5221.27 | F3: =F1+D11-E11 -> 1093.2 | I3: =I1+G127-H127 -> 116168.12 | L3: =L1+J11-K11 -> 96558 | O3: =O1+M21-N21 -> 31410 | R3: =R1+P14-Q14 -> 58950 | U3: =U1+S42-T42 -> 47375 | X3: =X1+V13-W13 -> 0 | AA3: =AA1+Y35-Z35 -> 0 | AD3: =AD1+AB14-AC14 -> 99.87 | AG3: =AG1+AE11-AF11 -> 13120 | AJ3: =AJ1+AH39-AI39 -> 0 | AM3: =AM1+AK15-AL15 -> 0 | AP3: =AP1+AN11-AO11 -> 0 | AS3: =AS1+AQ11-AR11 -> 0 | AV3: =AV1+AT11-AU11 -> 74414.81
B4: 7000 | D4: 1070 | G4: 177960 | J4: 96558 | M4: 32425 | Q4: 15200 | S4: 49290 | V4: 34000 | Z4: 39072 | AB4: 46400 | AH4: 125 | AN4: 353.57 | AT4: 87330
B5: 7000 | E5: 528.2 | H5: 6803.17 | M5: 13615 | P5: 58950 | S5: 20655 | W5: 34000 | Z5: 7084 | AB5: 12.8 | AI5: 125 | AN5: 381.87 | AT5: 84.81
B6: 7000 | E6: 600 | H6: 2003 | N6: 46040 | T6: 4950 | Y6: 488400 | AC6: 46400 | AH6: 116 | AO6: 353.57 | AU6: 7000
A7: 15300 | E7: 320 | H7: 1465 | M7: 31410 | T7: 2000 | Z7: 24420 | AI7: 116 | AO7: 381.87 | AT7: 1000
A8: 63.25 | H8: 4040 | T8: 4000 | Z8: 34188 | AH8: 113 | AU8: 7000
B9: 7000 | H9: 4290 | T9: 8200 | Y9: 9900 | AI9: 113
B10: 7000 | H10: 900 | T10: 3500 | Z10: 19976
D11: =SUM(D4:D10) -> 1070 | E11: =SUM(E4:E10) -> 1448.2 | H11: 1850 | J11: =SUM(J4:J10) -> 96558 | K11: =SUM(K4:K10) -> 0 | T11: 3000 | Z11: 19976 | AE11: =SUM(AE4:AE10) -> 0 | AF11: =SUM(AF4:AF10) -> 0 | AN11: =SUM(AN4:AN10) -> 735.44 | AO11: =SUM(AO4:AO10) -> 735.44 | AQ11: =SUM(AQ4:AQ10) -> 0 | AR11: =SUM(AR4:AR10) -> 0 | AT11: =SUM(AT4:AT10) -> 88414.81 | AU11: =SUM(AU4:AU10) -> 14000
H12: 3400 | T12: 7200 | Z12: 19976
H13: 12500 | T13: 5600 | V13: =SUM(V4:V12) -> 34000 | W13: =SUM(W4:W12) -> 34000 | Z13: 29964
H14: 3100 | P14: =SUM(P4:P13) -> 58950 | Q14: =SUM(Q4:Q13) -> 15200 | T14: 15890 | Z14: 44946 | AB14: =SUM(AB4:AB13) -> 46412.8 | AC14: =SUM(AC4:AC13) -> 46400
H15: 3000 | T15: 6090 | Z15: 4994 | AK15: =SUM(AK4:AK14) -> 0 | AL15: =SUM(AL4:AL14) -> 0
H16: 1605 | T16: 9345 | Z16: 49940
H17: 2896 | T17: 8900 | Z17: 44946
H18: 4858.53 | T18: 5000 | Z18: 44946
H19: 1000 | T19: 14520 | Z19: 54934
H20: 11600 | S20: 47295 | Z20: 44946
H21: 2300 | M21: =SUM(M4:M20) -> 77450 | N21: =SUM(N4:N20) -> 46040 | Z21: 59928
H22: 2925 | Z22: 220
H23: 3000
H24: 1350
H25: 3900
H26: 720
H27: 6208
H28: 6024.43
G29: 74580
H30: 4765
H31: 4960
H32: 4515
H33: 3860
H34: 4980
H35: 4900 | Y35: =SUM(Y4:Y34) -> 498300 | Z35: =SUM(Z4:Z34) -> 544456
H36: 4620
H37: 1785
H38: 11300
H39: 1350 | AH39: =SUM(AH4:AH38) -> 354 | AI39: =SUM(AI4:AI38) -> 354
H40: 4976.06
...

Sheet เงินเดือนครู
B2: 13 หลัก | D2: ต.ค.66 | E2: พ.ย.66 | F2: ธ.ค.66 | G2: ม.ค.67 | H2: ก.พ.67 | I2: มี.ค 67 | J2: รวม | K2: เม.ย.67 | L2: พ.ค.67 | M2: มิ.ย.67 | N2: ก.ค.67 | O2: ส.ค.67 | P2: ก.ย.67 | Q2: รวม
A3: 1 | B3: 3610400224673 | C3: ผอ. | D3: 54760 | E3: 57980 | F3: 56370 | G3: 56370 | H3: 56370 | I3: 56370 | J3: =SUM(D3:I3) -> 338220 | K3: 56370 | L3: 56370 | M3: 61110 | N3: 57950 | O3: 57950 | P3: 57950 | Q3: =SUM(K3:P3) -> 347700
A4: 2 | B4: 3610400253258 | C4: ยา | D4: 79090 | E4: 82552.96 | F4: 80821.48 | G4: 80821.48 | H4: 80821.48 | I4: 80821.48 | J4: =SUM(D4:I4) -> 484928.88 | K4: 80240 | L4: 80240 | M4: 84679.7 | N4: 81719.9 | O4: 81719.9 | P4: 81719.9 | Q4: =SUM(K4:P4) -> 490319.4
A5: 3 | B5: 3610400272708 | C5: นารี | D5: 76120 | E5: 79140 | F5: 77630 | G5: 77630 | H5: 77630 | I5: 77630 | J5: =SUM(D5:I5) -> 465780 | K5: 77630 | L5: 77630 | M5: 82700 | N5: 79320 | O5: 79320 | P5: 79320 | Q5: =SUM(K5:P5) -> 475920
A6: 5 | B6: 3610500024391 | C6: แมว | D6: 78880 | E6: 81839.8 | F6: 80359.9 | G6: 80359.9 | H6: 80359.9 | I6: 80359.9 | J6: =SUM(D6:I6) -> 482159.4 | K6: 80240 | L6: 80240 | M6: 85271.66 | N6: 81917.22 | O6: 81917.22 | P6: 81917.22 | Q6: =SUM(K6:P6) -> 491503.32
A7: 6 | B7: 3610500109671 | C7: แก้ว | D7: 66640 | E7: 70120 | F7: 68380 | G7: 68380 | H7: 68380 | I7: 68380 | J7: =SUM(D7:I7) -> 410280 | K7: 68380 | L7: 68380 | M7: 72910 | N7: 69890 | O7: 69890 | P7: 69890 | Q7: =SUM(K7:P7) -> 419340
A8: 7 | B8: 3610200328211 | C8: กาญ | D8: 56270 | E8: 59750 | F8: 58010 | G8: 58010 | H8: 58010 | I8: 58010 | J8: =SUM(D8:I8) -> 348060 | K8: 58010 | L8: 58010 | M8: 62450 | N8: 59490 | O8: 59490 | P8: 59490 | Q8: =SUM(K8:P8) -> 356940
A9: 8 | B9: 3100503688812 | C9: สรคม | D9: 53850 | E9: 57330 | F9: 55590 | G9: 55590 | H9: 55590 | I9: 55590 | J9: =SUM(D9:I9) -> 333540 | K9: 55590 | L9: 55590 | M9: 60030 | N9: 57070 | O9: 57070 | P9: 57070 | Q9: =SUM(K9:P9) -> 342420
A10: 9 | B10: 3610500159091 | C10: ตุ๊ก | D10: 56230 | E10: 59710 | F10: 57970 | G10: 57970 | H10: 57970 | I10: 57970 | J10: =SUM(D10:I10) -> 347820 | K10: 57970 | L10: 57970 | M10: 62410 | N10: 59450 | O10: 59450 | P10: 59450 | Q10: =SUM(K10:P10) -> 356700
A11: 10 | B11: 1610600135741 | C11: ส้ม | D11: 21280 | E11: 22700 | F11: 21990 | G11: 21990 | H11: 21990 | I11: 21990 | J11: =SUM(D11:I11) -> 131940 | K11: 21990 | L11: 21990 | M11: 24360 | N11: 25720 | O11: 25720 | P11: 25720 | Q11: =SUM(K11:P11) -> 145500
A12: 11 | B12: 1619900117517 | C12: ใหม่ | D12: 18680 | E12: 20080 | F12: 19380 | G12: 19380 | H12: 19380 | I12: 19380 | J12: =SUM(D12:I12) -> 116280 | K12: 19380 | L12: 19380 | M12: 21750 | N12: 24310 | O12: 21550 | P12: 21550 | Q12: =SUM(K12:P12) -> 127920
A13: 12 | B13: 1619900176173 | C13: แจ๊ก | D13: 15800 | E13: 15800 | F13: 15800 | G13: 15800 | H13: 15800 | I13: 15800 | J13: =SUM(D13:I13) -> 94800 | K13: 15800 | L13: 15800 | M13: 17630 | N13: 21150 | O13: 17990 | P13: 17990 | Q13: =SUM(K13:P13) -> 106360
A14: 13 | B14: 1100702961148 | C14: ภาม | G14: 39500 | H14: 15800 | I14: 15800 | J14: =SUM(D14:I14) -> 71100 | K14: 15800 | L14: 15800 | M14: 17390 | N14: 21070 | O14: 17910 | P14: 17910 | Q14: =SUM(K14:P14) -> 105880
J15: =SUM(J3:J14) -> 3624908.3 | Q15: =SUM(Q3:Q14) -> 3766502.7
C17: หน่อย | D17: 15000 | E17: 15000 | F17: 15000 | G17: 15000 | H17: 15000 | I17: 15000 | J17: =SUM(D17:I17) -> 90000 | K17: 15000 | L17: 15000 | M17: 15000 | N17: 15000 | O17: 15000 | P17: 15000 | Q17: =SUM(K17:P17) -> 90000
C18: นิค | D18: 9000 | E18: 9000 | F18: 9000 | G18: 9000 | H18: 9000 | I18: 9000 | J18: =SUM(D18:I18) -> 54000 | K18: 9000 | L18: 9000 | M18: 9000 | N18: 9000 | O18: 9000 | P18: 9000 | Q18: =SUM(K18:P18) -> 54000
C19: จอก | D19: 9000 | E19: 9000 | F19: 9000 | G19: 9000 | H19: 9000 | I19: 9000 | J19: =SUM(D19:I19) -> 54000 | K19: 9000 | L19: 9000 | M19: 9000 | N19: 9000 | O19: 9000 | P19: 9000 | Q19: =SUM(K19:P19) -> 54000
C20: พร | D20: 6000 | E20: 6000 | F20: 6000 | G20: 6000 | H20: 6000 | I20: 6000 | J20: =SUM(D20:I20) -> 36000 | K20: 6000 | L20: 6000 | M20: 6000 | N20: 6000 | O20: 6000 | P20: 6000 | Q20: =SUM(K20:P20) -> 36000
C21: เจน | D21: 6000 | E21: 6000 | F21: 6000 | G21: 6000 | H21: 6000 | I21: 6000 | J21: =SUM(D21:I21) -> 36000 | K21: 6000 | L21: 6000 | M21: 6000 | N21: 6000 | O21: 6000 | P21: 6000 | Q21: =SUM(K21:P21) -> 36000
B23: 13 หลัก | D23: ต.ค.67 | E23: พ.ย.67 | F23: ธ.ค.67 | G23: ม.ค.68 | H23: ก.พ.68 | I23: มี.ค 68 | J23: รวม | K23: เม.ย.68 | L23: พ.ค.68 | M23: มิ.ย.68 | N23: ก.ค.68 | O23: ส.ค.68 | P23: ก.ย.68 | Q23: รวม
A24: 1 | B24: 3610400224673 | C24: ผอ. | D24: 57950 | E24: 61070 | F24: 59510 | G24: 59510 | H24: 59510 | I24: 59510 | J24: =SUM(D24:I24) -> 357060 | K24: 59510 | L24: 62570 | M24: 61040 | N24: 61040 | O24: 61040 | P24: 61040 | Q24: =SUM(K24:P24) -> 366240
A25: 2 | B25: 3610500109671 | C25: แก้ว | D25: 69890 | E25: 69890 | F25: 76550 | G25: 72110 | H25: 72110 | I25: 72110 | J25: =SUM(D25:I25) -> 432660 | K25: 72110 | L25: 72110 | M25: 76940 | N25: 73720 | O25: 73720 | P25: 73720 | Q25: =SUM(K25:P25) -> 442320
A26: 3 | B26: 3610200328211 | C26: กาญ | D26: 59490 | E26: 59490 | F26: 66150 | G26: 61710 | H26: 61710 | I26: 61710 | J26: =SUM(D26:I26) -> 370260 | K26: 61710 | L26: 61710 | M26: 66180 | N26: 63200 | O26: 63200 | P26: 63200 | Q26: =SUM(K26:P26) -> 379200
A27: 4 | B27: 3610500159091 | C27: ตุ๊ก | D27: 59450 | E27: 59450 | F27: 66110 | G27: 61670 | H27: 61670 | I27: 61670 | J27: =SUM(D27:I27) -> 370020 | K27: 61670 | L27: 61670 | M27: 66500 | N27: 63280 | O27: 63280 | P27: 63280 | Q27: =SUM(K27:P27) -> 379680
A28: 5 | B28: 3100503688812 | C28: สรคม | D28: 57070 | E28: 57070 | F28: 63730 | G28: 59290 | H28: 59290 | I28: 59290 | J28: =SUM(D28:I28) -> 355740 | K28: 59290 | L28: 59290 | M28: 63850 | N28: 60810 | O28: 60810 | P28: 60810 | Q28: =SUM(K28:P28) -> 364860
A29: 6 | B29: 1610600135741 | C29: ส้ม | D29: 25720 | E29: 25720 | F29: 26850 | G29: 24790 | H29: 24790 | I29: 24790 | J29: =SUM(D29:I29) -> 152660 | K29: 24790 | L29: 24790 | M29: 27040 | N29: 25540 | O29: 25540 | P29: 25540 | Q29: =SUM(K29:P29) -> 153240
A30: 7 | B30: 1619900117517 | C30: ใหม่ | D30: 21550 | E30: 21550 | F30: 24640 | G30: 22580 | H30: 22580 | I30: 22580 | J30: =SUM(D30:I30) -> 135480 | K30: 22580 | L30: 22580 | M30: 24830 | N30: 23330 | O30: 23330 | P30: 23330 | Q30: =SUM(K30:P30) -> 139980
A31: 8 | B31: 1619900176173 | C31: แจ๊ก | D31: 17990 | E31: 17990 | F31: 20360 | G31: 18780 | H31: 18780 | I31: 18780 | J31: =SUM(D31:I31) -> 112680 | K31: 18780 | L31: 18780 | M31: 20400 | N31: 19320 | O31: 26280 | P31: 21060 | Q31: =SUM(K31:P31) -> 124620
A32: 9 | B32: 1100702961148 | C32: ภาม | D32: 17910 | E32: 17910 | F32: 20280 | G32: 18700 | H32: 18700 | I32: 18700 | J32: =SUM(D32:I32) -> 112200 | K32: 18700 | L32: 18700 | M32: 20410 | N32: 19270 | O32: 26230 | P32: 21010 | Q32: =SUM(K32:P32) -> 124320
A33: 10 | B33: 1619900187051 | C33: เดียร์ | G33: 32480 | H33: 32480 | I33: 32480 | J33: =SUM(D33:I33) -> 97440 | K33: 32480 | L33: 32480 | M33: 35240 | N33: 33400 | O33: 36840 | P33: 34260 | Q33: =SUM(K33:P33) -> 204700
A34: 11 | B34: 1619900248042 | C34: ตง | G34: 20080 | H34: 20080 | I34: 20080 | J34: =SUM(D34:I34) -> 60240 | K34: 20080 | L34: 20080 | M34: 22150 | N34: 20770 | O34: 26850 | P34: 22290 | Q34: =SUM(K34:P34) -> 132220
J35: =SUM(J24:J34) -> 2556440 | Q35: =SUM(Q24:Q34) -> 2811380
C37: หน่อย | D37: 15000 | E37: 15000 | F37: 15000 | G37: 15000 | H37: 15000 | I37: 15000 | J37: =SUM(D37:I37) -> 90000 | K37: 15000 | L37: 15000 | M37: 15000 | N37: 15000 | O37: 15000 | P37: 15000 | Q37: =SUM(K37:P37) -> 90000
C38: นิค | D38: 9000 | E38: 9000 | F38: 9000 | G38: 9000 | H38: 9000 | I38: 9000 | J38: =SUM(D38:I38) -> 54000 | K38: 9000 | L38: 9000 | M38: 9000 | N38: 9000 | O38: 9000 | P38: 9000 | Q38: =SUM(K38:P38) -> 54000
C39: จอก | D39: 9000 | E39: 9000 | F39: 9000 | G39: 9000 | H39: 9000 | I39: 9000 | J39: =SUM(D39:I39) -> 54000 | K39: 9000 | L39: 9000 | M39: 9000 | N39: 9000 | O39: 9000 | P39: 9000 | Q39: =SUM(K39:P39) -> 54000
C40: พร | D40: 6000 | E40: 6000 | F40: 6000 | G40: 6000 | H40: 6000 | I40: 6000 | J40: =SUM(D40:I40) -> 36000 | K40: 6000 | L40: 6000 | M40: 6000 | N40: 6000 | O40: 6000 | P40: 6000 | Q40: =SUM(K40:P40) -> 36000
C41: เจน | D41: 6000 | E41: 6000 | F41: 6000 | G41: 6000 | J41: =SUM(D41:I41) -> 24000 | Q41: =SUM(K41:P41) -> 0
B46: 13 หลัก | D46: ตค68 | E46: พย68 | F46: ธค68 | G46: มค69 | H46: กพ69 | I46: มีค69 | J46: รวม | K46: เม.ย.68 | L46: พ.ค.68 | M46: มิ.ย.68 | N46: ก.ค.68 | O46: ส.ค.68 | P46: ก.ย.68 | Q46: รวม
B47: 3610400224673 | C47: ผอ. | D47: 61040 | E47: 64160 | F47: 62600 | G47: 62600 | H47: 62600 | I47: 62600 | J47: =SUM(D47:I47) -> 375600
B48: 3610500109671 | C48: แก้ว | D48: 73720 | E48: 73720 | F48: 78100 | G48: 75180 | H48: 75180 | I48: 75180 | J48: =SUM(D48:I48) -> 451080
...

Sheet รายรับ ปีงบ 2569-1
A1: 2.1(1) รายหัว | B1: 2.1(2) ค่าหนังสือเรียน | C1: 2.1(3) ค่าอุปกรณ์การเรียน | D1: 2.1(4) ค่าเครื่องแบบนักเรียน | E1: 2.1(5) ค่ากิจกรรมพัฒนาคุณภาพผู้เรียน | F1: 2.1(6) ปัจจัยพื้นฐานสำหรับนักเรียนยากจน | G1: 3.3 ปัจจัยพื้นฐานสำหรับนักเรียนยากจน (กสศ) | H1: 4.2 อาหารกลางวัน | I1: 5.2 รายได้สถานศึกษา | J1: 5.5 เงินประกันสัญญา | K1: (5.6) เงินภาษี หัก ณ ที่จ่าย | L1: 5.7 ลูกเสือ | M1: (6.4) รายได้แผ่นดิน ดอกเบี้ยเงินฝาก
A2: 177960 | C2: 32425 | E2: 49290 | G2: 46400 | H2: 488400 | I2: 15300 | K2: 125 | L2: 1070 | M2: 353.57
A3: 74580 | C3: 13615 | E3: 20655 | F3: 34000 | G3: 12.8 | H3: 9900 | I3: 63.25 | K3: 116 | M3: 381.87
I4: 87330 | K4: 113
I5: 84.81
I6: 1000
A10: =SUM(A2:A9) -> 252540 | B10: =SUM(B2:B9) -> 0 | C10: =SUM(C2:C9) -> 46040 | D10: =SUM(D2:D9) -> 0 | E10: =SUM(E2:E9) -> 69945 | F10: =SUM(F2:F9) -> 34000 | G10: =SUM(G2:G9) -> 46412.8 | H10: =SUM(H2:H9) -> 498300 | ... M10: =SUM(M2:M9) -> 735.44

Sheet รายรับ ปีงบ 2568-2
A1: 2.1(1) จัดการเรียนการสอน(รายหัว) | B1: 2.1(2) ค่าหนังสือเรียน | C1: 2.1(3) ค่าอุปกรณ์การเรียน | D1: 2.1(4) ค่าเครื่องแบบนักเรียน | E1: 2.1(5) ค่ากิจกรรมพัฒนาคุณภาพผู้เรียน | F1: 2.1(6) ปัจจัยพื้นฐานสำหรับนักเรียนยากจน | G1: 3.3 ปัจจัยพื้นฐานสำหรับนักเรียนยากจน (กสศ) | H1: 4.2 อาหารกลางวัน | I1: 5.2 รายได้สถานศึกษา(เงินบริจาค) | J1: 5.5 เงินประกันสัญญา | K1: (5.6) เงินภาษี หัก ณ ที่จ่าย | L1: 5.7 ลูกเสือ | M1: (6.4) รายได้แผ่นดิน ดอกเบี้ยเงินฝาก | N1: 5.10 เงินอุดหนุนอบรมลูกเสือ
G2: 5.35 | I2: 213.15 | K2: 62 | N2: 20000
B3: 31129 | D3: 20150 | F3: 17500 | G3: 32800 | I3: 22000 | K3: 279.22
B4: 31278 | F4: 16500 | G4: 13600 | H4: 246400 | I4: 3000 | M4: 931.7
A5: 56616 | C5: 10670 | D5: 18025 | E5: 14090 | H5: 244200 | I5: 3500 | M5: 327.93
A6: 50112 | D6: 15200 | E6: 12459 | I6: 1000
C7: 9745
K8: 518
K9: 292.5
A10: =SUM(A2:A9) -> 106728 | B10: =SUM(B2:B9) -> 62407 | C10: =SUM(C2:C9) -> 20415 | D10: =SUM(D2:D9) -> 53375 | E10: =SUM(E2:E9) -> 26549 | F10: =SUM(F2:F9) -> 34000 | G10: =SUM(G2:G9) -> 46405.35 | H10: =SUM(H2:H9) -> 490600 | J10: =SUM(J2:J9) -> 0 | K10: 152 | L10: =SUM(L2:L9) -> 0 | M10: =SUM(M2:M9) -> 1259.63 | N10: =SUM(N2:N9) -> 20000
K11: 52.6
K12: 133.2
K13: 1350.07
I14: =SUM(I2:I13) -> 29713.15 | K14: 200
K15: 200
K16: 70
K17: 26.17
K19: =SUM(K2:K18) -> 3335.76

Sheet บันทึกรายจ่าย 68-2
A1: รอบที่ 1
A2: 1. ด้านวิชาการ | H2: 2. ด้านบริหารงานบุคคล | L2: 3. ด้านการบริหารงบประมาณ | S2: 4. ด้านการบริหารทั่วไป | Y2: 5. กิจการนักเรียน | AE2: 6. เงินรายได้แผ่นดิน
A3: 1.1 โครงการ/กิจกรรมตามแผน | B3: 1.2หนังสือห้องสมุด | C3: 1.3หนังสือเรียน | D3: 1.4อุปรณ์การเรียน | E3: 1.5เครื่องแบบนักเรียน | F3: 1.6กิจกรรมพัฒนาผู้เรียน | G3: 1.7 อื่นๆ | H3: 4. จ้างครูอัตราจ้างรายเดือนโดยใช้เงินอื่นๆ(เงินบริจาค) | I3: 8. ค่าตอบแทนวิยากรภายนอกรายช่วโมง | J3: 2.2 โครงการพัฒนาบุคคลากรตามแผนปฏิบัติการ | K3: 2.3 อื่นๆ | L3: 3.1 ค่าครุภัณฑ์ | M3: 3.2 ค่าซ่อมแซม | N3: 3.3 ก่อสร้างอาคารเรียน อาคารประกอบ | O3: 3.4 ค่าปรับปรุง/ขยายเขตระบบไฟฟ้า | P3: 3.5 ค่าปรับปรุงซ่อมแซมอาคาร อาคารประกอบ | Q3: 3.7 โครงการบริหารงบประมาณตามแผนฯ | R3: 3.8 อื่นๆ | S3: ค่าไฟฟ้า | T3: ค่าเบี้ยเลี้ยงเลี้ยง ค่าที่พัก ค่าพาหณะ | U3: ค่าวัสดุ | V3: เงินหักภาษี ณที่จ่าย | W3: โครงการบริหารทั่วไปตามแผนปฏิบัติการฯ | X3: อื่นๆ | Y3: 5.1 ปัจจัยพื้นฐานนักเรียนยากจน | Z3: 5.3 ค่าอาหารกลางวันจาก อบต. | AA3: 5.4 เงินลูกเสือ | AB3: 5.9 โครงการงานกิจกรรมนักเรียนตามแผนฯ | AC3: 5.10 อื่นๆ (ทุน กสศ.) | AE3: 6.1 ค่าขายของเบ็ตเล็ต | AF3: 6.4 ดอกเบี้ยเงินฝาก | AG3: 6.5 อื่นๆ | AH3: 5.10ทุน(เงินบริจาค)
A4: 1981 | D4: 45900 | F4: 2500 | H4: 12000 | J4: 300 | L4: 17301.69 | M4: 14100 | P4: 54000 | Q4: 4830 | S4: 6332.67 | U4: 3415 | V4: 564.6 | W4: 365 | Y4: 8000 | Z4: 39072 | AA4: 507.45 | AB4: 4500 | AC4: 29140 | AF4: 1615.74 | AH4: 20000
A5: 2105 | F5: 11200 | H5: 12000 | L5: 600 | M5: 1000 | Q5: 2150 | S5: 5213.11 | U5: 2520 | V5: 141 | W5: 840 | Y5: 17000 | Z5: 9416 | AB5: 3500 | AC5: 37840
A6: 2534 | F6: 14280 | H6: 12000 | M6: 2000 | Q6: 1825 | S6: 6802.61 | V6: 281 | W6: 645 | Y6: 24500 | Z6: 53240 | AB6: 8500
A7: 4530 | F7: 5400 | H7: 12000 | M7: 16900 | Q7: 1840 | S7: 4355.62 | V7: 713.02 | W7: 2890 | Z7: 49500 | AB7: 8000
A8: 3390 | H8: 6000 | M8: 2900 | S8: 4186.34 | V8: 142.8 | W8: 4715 | Z8: 39600 | AB8: 4500
A9: 500 | H9: 6000 | M9: 1200 | S9: 7613.09 | W9: 322 | Z9: 49500 | AB9: 1000
A10: 1500 | M10: 9000 | W10: 1200 | Z10: 34650 | AB10: 2095
A11: 1890 | M11: 4600 | Z11: 74250 | AB11: 4800
A12: 3195 | M12: 2120 | Z12: 39600 | AB12: 805
A13: 4800 | M13: 4150 | Z13: 49500 | AB13: 1800
A14: 1939 | Z14: 49500 | AB14: 3025
A15: 3585 | Z15: 54450
A16: 3407
A17: 1029
A18: 1865
A19: 1950
A21: =SUM(A4:A19) -> 40200 | B21: =SUM(B4:B19) -> 0 | C21: =SUM(C4:C19) -> 0 | D21: =SUM(D4:D19) -> 45900 | E21: =SUM(E4:E19) -> 0 | F21: =SUM(F4:F19) -> 33380 | G21: =SUM(G4:G19) -> 0 | H21: =SUM(H4:H19) -> 60000 | ... AC21: =SUM(AC4:AC19) -> 66980 | AE21: =SUM(AE4:AE19) -> 0 | AF21: =SUM(AF4:AF19) -> 1615.74 | AG21: =SUM(AG4:AG19) -> 0 | AH21: =SUM(AH4:AH19) -> 20000
A22: รอบที่ 2
A23: 1. ด้านวิชาการ | H23: 2. ด้านบริหารงานบุคคล | L23: 3. ด้านการบริหารงบประมาณ | S23: 4. ด้านการบริหารทั่วไป | Y23: 5. กิจการนักเรียน | AE23: 6. เงินรายได้แผ่นดิน
A24: 1.1 โครงการ/กิจกรรมตามแผน | B24: 1.2หนังสือห้องสมุด | C24: 1.3หนังสือเรียน | D24: 1.4อุปรณ์การเรียน | E24: 1.5เครื่องแบบนักเรียน | F24: 1.6กิจกรรมพัฒนาผู้เรียน | G24: 1.7 อื่นๆ | H24: 4. จ้างครูอัตราจ้างรายเดือนโดยใช้เงินอื่นๆ | I24: 8. ค่าตอบแทนวิยากรภายนอกรายช่วโมง | J24: 2.2 โครงการพัฒนาบุคคลากรตามแผนปฏิบัติการ | K24: 2.3 อื่นๆ | L24: 3.1 ค่าครุภัณฑ์ | M24: 3.2 ค่าซ่อมแซม | N24: 3.3 ก่อสร้างอาคารเรียน อาคารประกอบ | O24: 3.4 ค่าปรับปรุง/ขยายเขตระบบไฟฟ้า | P24: 3.5 ค่าปรับปรุงซ่อมแซมอาคาร อาคารประกอบ | Q24: 3.7 โครงการบริหารงบประมาณตามแผนฯ | R24: 3.8 อื่นๆ | S24: ค่าไฟฟ้า | T24: ค่าเบี้ยเลี้ยงเลี้ยง ค่าที่พัก ค่าพาหณะ | U24: ค่าวัสดุ | V24: เงินหักภาษี ณที่จ่าย | W24: โครงการบริหารทั่วไปตามแผนปฏิบัติการฯ | X24: อื่นๆ | Y24: 5.1 ปัจจัยพื้นฐานนักเรียนยากจน | Z24: 5.3 ค่าอาหารกลางวันจาก อบต. | AA24: 5.4 เงินลูกเสือ | AB24: 5.9 โครงการงานกิจกรรมนักเรียนตามแผนฯ | AC24: 5.10 อื่นๆ (ทุน กสศ.) | AD24: 5.11 ทุนการศึกษา | AE24: 6.1 ค่าขายของเบ็ตเล็ต | AF24: 6.4 ดอกเบี้ยเงินฝาก | AG24: 6.5 อื่นๆ | AH24: เงินประกันสัญญา | AI24: อบรมลูกเสือ | AJ24: 6.1
A25: 5628 | C25: 135007 | D25: 44430 | E25: 83850 | F25: 7000 | H25: 6000 | L25: 55426 | M25: 29250 | O25: 1800 | Q25: 3100 | S25: 5234.02 | V25: 518 | W25: 3600 | Y25: 17500 | AA25: 280 | AB25: 720 | AC25: 32800 | AD25: 22000 | AF25: 1259.63 | AI25: 720 | AJ25: 110
A26: 2590 | D26: 585 | E26: 1125 | F26: 720 | H26: 6000 | M26: 15200 | Q26: 209 | S26: 3154.54 | V26: 444.5 | W26: 320 | Y26: 16500 | Z26: 53724 | AB26: 4985 | AC26: 13600 | AI26: 1220
A27: 418 | F27: 13320 | H27: 6000 | M27: 850 | Q27: 27922 | S27: 7587.3 | V27: 52.6 | W27: 620 | Z27: 48840 | AB27: 4950 | AI27: 18060
A28: 4930 | F28: 3000 | H28: 6000 | M28: 1820 | Q28: 3970 | S28: 8364.89 | V28: 62 | W28: 4730 | Z28: 43956 | AB28: 2435
A29: 4615 | F29: 1890 | H29: 6000 | M29: 1300 | S29: 7758.61 | V29: 279.22 | W29: 4400 | Z29: 34188 | AB29: 4932
A30: 6200 | F30: 720 | H30: 6000 | M30: 3000 | S30: 9335.09 | V30: 133.2 | W30: 3255 | Z30: 63492 | AB30: 2520
A31: 2100 | F31: 20000 | M31: 1000 | V31: 1350.07 | W31: 2640 | Z31: 43956 | AB31: 3080
A32: 2160 | F32: 6000 | M32: 7000 | V32: 400 | Z32: 48840 | AB32: 3080
A33: 4555 | F33: 6000 | M33: 2000 | V33: 96.17 | Z33: 48840
A34: 2237 | F34: 20000 | M34: 990 | Z34: 58608
A35: 4925 | F35: 4000 | M35: 950
A36: 510 | F36: 250
A37: 2010 | F37: 250
A38: 1600 | F38: 3600
A39: 4850 | F39: 5950
A40: 4795 | F40: 7000
A41: 3000 | F41: 6020
...

Sheet บันทึกรายจ่าย 68-1
A1: รอบที่ 1
A2: 1. ด้านวิชาการ | H2: 2. ด้านบริหารงานบุคคล | L2: 3. ด้านการบริหารงบประมาณ | S2: 4. ด้านการบริหารทั่วไป | Y2: 5. กิจการนักเรียน | AD2: 6. เงินรายได้แผ่นดิน
A3: 1.1 โครงการ/กิจกรรมตามแผน | B3: 1.2หนังสือห้องสมุด | C3: 1.3หนังสือเรียน | D3: 1.4อุปรณ์การเรียน | E3: 1.5เครื่องแบบนักเรียน | F3: 1.6กิจกรรมพัฒนาผู้เรียน | G3: 1.7 อื่นๆ | H3: 4. จ้างครูอัตราจ้างรายเดือนโดยใช้เงินอื่นๆ(เงินบริจาค) | I3: 8. ค่าตอบแทนวิยากรภายนอกรายช่วโมง | J3: 2.2 โครงการพัฒนาบุคคลากรตามแผนปฏิบัติการ | K3: 2.3 อื่นๆ | L3: 3.1 ค่าครุภัณฑ์ | M3: 3.2 ค่าซ่อมแซม | N3: 3.3 ก่อสร้างอาคารเรียน อาคารประกอบ | O3: 3.4 ค่าปรับปรุง/ขยายเขตระบบไฟฟ้า | P3: 3.5 ค่าปรับปรุงซ่อมแซมอาคาร อาคารประกอบ | Q3: 3.7 โครงการบริหารงบประมาณตามแผนฯ | R3: 3.8 อื่นๆ | S3: ค่าไฟฟ้า | T3: ค่าเบี้ยเลี้ยงเลี้ยง ค่าที่พัก ค่าพาหณะ | U3: ค่าวัสดุ | V3: เงินหักภาษี ณที่จ่าย | W3: โครงการบริหารทั่วไปตามแผนปฏิบัติการฯ | X3: อื่นๆ | Y3: 5.1 ปัจจัยพื้นฐานนักเรียนยากจน | Z3: 5.3 ค่าอาหารกลางวันจาก อบต. | AA3: 5.4 เงินลูกเสือ | AB3: 5.9 โครงการงานกิจกรรมนักเรียนตามแผนฯ | AC3: 5.10 อื่นๆ (ทุน กสศ.) | AD3: 6.1 ค่าขายของเบ็ตเล็ต | AE3: 6.4 ดอกเบี้ยเงินฝาก | AF3: 6.5 อื่นๆ | AG3: 5.10ทุน(เงินบริจาค)
A4: 1981 | D4: 45900 | F4: 2500 | H4: 12000 | J4: 300 | L4: 17301.69 | M4: 14100 | P4: 54000 | Q4: 4830 | S4: 6332.67 | U4: 3415 | V4: 564.6 | W4: 365 | Y4: 8000 | Z4: 39072 | AA4: 507.45 | AB4: 4500 | AC4: 29140 | AE4: 1615.74 | AG4: 20000
A5: 2105 | F5: 11200 | H5: 12000 | L5: 600 | M5: 1000 | Q5: 2150 | S5: 5213.11 | U5: 2520 | V5: 141 | W5: 840 | Y5: 17000 | Z5: 9416 | AB5: 3500 | AC5: 37840
A6: 2534 | F6: 14280 | H6: 12000 | M6: 2000 | Q6: 1825 | S6: 6802.61 | V6: 281 | W6: 645 | Y6: 24500 | Z6: 53240 | AB6: 8500
A7: 4530 | F7: 5400 | H7: 12000 | M7: 16900 | Q7: 1840 | S7: 4355.62 | V7: 713.02 | W7: 2890 | Z7: 49500 | AB7: 8000
A8: 3390 | H8: 6000 | M8: 2900 | S8: 4186.34 | V8: 142.8 | W8: 4715 | Z8: 39600 | AB8: 4500
A9: 500 | H9: 6000 | M9: 1200 | S9: 7613.09 | W9: 322 | Z9: 49500 | AB9: 1000
A10: 1500 | M10: 9000 | W10: 1200 | Z10: 34650 | AB10: 2095
A11: 1890 | M11: 4600 | Z11: 74250 | AB11: 4800
A12: 3195 | M12: 2120 | Z12: 39600 | AB12: 805
A13: 4800 | M13: 4150 | Z13: 49500 | AB13: 1800
A14: 1939 | Z14: 49500 | AB14: 3025
A15: 3585 | Z15: 54450
A16: 3407
A17: 1029
A18: 1865
A19: 1950
A21: =SUM(A4:A19) -> 40200 | B21: =SUM(B4:B19) -> 0 | C21: =SUM(C4:C19) -> 0 | D21: =SUM(D4:D19) -> 45900 | E21: =SUM(E4:E19) -> 0 | F21: =SUM(F4:F19) -> 33380 | G21: =SUM(G4:G19) -> 0 | H21: =SUM(H4:H19) -> 60000 | ... AG21: =SUM(AG4:AG19) -> 20000
A22: รอบที่ 2
A23: 1. ด้านวิชาการ | H23: 2. ด้านบริหารงานบุคคล | L23: 3. ด้านการบริหารงบประมาณ | S23: 4. ด้านการบริหารทั่วไป | Y23: 5. กิจการนักเรียน | AD23: 6. เงินรายได้แผ่นดิน
A24: 1.1 โครงการ/กิจกรรมตามแผน | B24: 1.2หนังสือห้องสมุด | C24: 1.3หนังสือเรียน | D24: 1.4อุปรณ์การเรียน | E24: 1.5เครื่องแบบนักเรียน | F24: 1.6กิจกรรมพัฒนาผู้เรียน | G24: 1.7 อื่นๆ | H24: 4. จ้างครูอัตราจ้างรายเดือนโดยใช้เงินอื่นๆ | I24: 8. ค่าตอบแทนวิยากรภายนอกรายช่วโมง | J24: 2.2 โครงการพัฒนาบุคคลากรตามแผนปฏิบัติการ | K24: 2.3 อื่นๆ | L24: 3.1 ค่าครุภัณฑ์ | M24: 3.2 ค่าซ่อมแซม | N24: 3.3 ก่อสร้างอาคารเรียน อาคารประกอบ | O24: 3.4 ค่าปรับปรุง/ขยายเขตระบบไฟฟ้า | P24: 3.5 ค่าปรับปรุงซ่อมแซมอาคาร อาคารประกอบ | Q24: 3.7 โครงการบริหารงบประมาณตามแผนฯ | R24: 3.8 อื่นๆ | S24: ค่าไฟฟ้า | T24: ค่าเบี้ยเลี้ยงเลี้ยง ค่าที่พัก ค่าพาหณะ | U24: ค่าวัสดุ | V24: เงินหักภาษี ณที่จ่าย | W24: โครงการบริหารทั่วไปตามแผนปฏิบัติการฯ | X24: อื่นๆ | Y24: 5.1 ปัจจัยพื้นฐานนักเรียนยากจน | Z24: 5.3 ค่าอาหารกลางวันจาก อบต. | AA24: 5.4 เงินลูกเสือ | AB24: 5.9 โครงการงานกิจกรรมนักเรียนตามแผนฯ | AC24: 5.10 อื่นๆ (ทุน กสศ.) | AD24: 6.1 ค่าขายของเบ็ตเล็ต | AE24: 6.4 ดอกเบี้ยเงินฝาก | AF24: 6.5 อื่นๆ | AG24: เงินประกันสัญญา | AH24: กองทุนหลักประกันสุขภาพ

Sheet แบบบันทึกรายจ่าย  ปีงบ2568-1
A1: ที่ | B1: รายจ่าย | D1: ครั้งที่ 1 ภาคเรียนที่ 2 | L1: ที่ | M1: รายจ่าย | O1: ครั้งที่ 2 ภาคเรียนที่ 1
D2: 1 ตุลาคม 67 - 31 มีนาคม 68 | O2: 1 เมษายน 68 - 30 กันยายน 68
D3: เงินงบประมาณ | E3: เงินนอกงบประมาณ | J3: เงินรายได้ แผ่นดิน | O3: เงินงบประมาณ | P3: เงินนอกงบประมาณ | U3: เงินรายได้ แผ่นดิน
E4: โครงการเรียนฟรี | F4: เงินบำรุง การศึกษา | G4: เงินบริจาค | H4: เงินรายได้ สถานศึกษา | I4: อื่น ๆ | P4: โครงการเรียนฟรี | Q4: เงินบำรุง การศึกษา | R4: เงินบริจาค | S4: เงินรายได้ สถานศึกษา | T4: อื่น ๆ
A5: 1. | B5: ด้านการบริหารงานวิชาการ | D5: 0 | E5: 0 | F5: 0 | G5: 0 | H5: 0 | I5: 0 | L5: 1. | M5: ด้านการบริหารงานวิชาการ | O5: 0 | P5: 0 | Q5: 0 | R5: 0 | S5: 0 | T5: 0
B6: 1.1 | C6: โครงการ/กิจกรรมการเรียนการสอนตามแผนปฏิบัติการประจำปี (ไม่รวมข้อ 1.2 -1.7) | E6: =#REF! -> #REF! | M6: 1.1 | N6: โครงการ/กิจกรรมการเรียนการสอนตามแผนปฏิบัติการประจำปี (ไม่รวมข้อ 1.2 -1.7) | P6: =#REF! -> #REF!
B7: 1.2 | C7: หนังสือห้องสมุด | M7: 1.2 | N7: หนังสือห้องสมุด
B8: 1.3 | C8: หนังสือเรียน | M8: 1.3 | N8: หนังสือเรียน | P8: =#REF! -> #REF!
B9: 1.4 | C9: อุปกรณ์การเรียน | E9: =#REF! -> #REF! | M9: 1.4 | N9: อุปกรณ์การเรียน | P9: =#REF! -> #REF!
B10: 1.5 | C10: เครื่องแบบนักเรียน | M10: 1.5 | N10: เครื่องแบบนักเรียน | P10: =#REF! -> #REF!
B11: 1.6 | C11: กิจกรรมพัฒนาคุณภาพผู้เรียน | E11: =#REF! -> #REF! | M11: 1.6 | N11: กิจกรรมพัฒนาคุณภาพผู้เรียน | P11: =#REF! -> #REF!
B12: 1.7 | C12: อื่น ๆ | M12: 1.7 | N12: อื่น ๆ
A13: 2. | B13: ด้านการบริหารงานบุคคล | D13: 0 | E13: 0 | F13: 0 | G13: 0 | H13: 0 | I13: 0 | L13: 2. | M13: ด้านการบริหารงานบุคคล | O13: 0 | P13: 0 | Q13: 0 | R13: 0 | S13: 0 | T13: 0
B14: 2.1 | C14: ค่าใช้จ่ายสำหรับบุคลากร | D14: 0 | E14: 0 | F14: 0 | G14: 0 | H14: 0 | I14: 0 | M14: 2.1 | N14: ค่าใช้จ่ายสำหรับบุคลากร | O14: 0 | P14: 0 | Q14: 0 | R14: 0 | S14: 0 | T14: 0
C15: (1) งบบุคลากร (เงินเดือน, ค่าจ้างประจำ, ค่าตอบแทนพนักงานราชการ วิทยฐานะ ค่าตอบแทนรายเดือน และ เงินที่จ่ายควบพร้อมเงินเดือน) [ส่วนที่ 3 ข้อ 2.3] | D15: 0 | N15: (1) งบบุคลากร (เงินเดือน, ค่าจ้างประจำ, ค่าตอบแทนพนักงานราชการ วิทยฐานะ ค่าตอบแทนรายเดือน และ เงินที่จ่ายควบพร้อมเงินเดือน) [ส่วนที่ 3 ข้อ 2.3] | O15: 0
C16: (2) ค่าจ้างครูอัตราจ้างรายเดือน โดย สพฐ. [ส่วนที่ 3 ข้อ 2.4(1)] | D16: 0 | N16: (2) ค่าจ้างครูอัตราจ้างรายเดือน โดย สพฐ. [ส่วนที่ 3 ข้อ 2.4(1)] | O16: 0
C17: (3) ค่าจ้างครูและบุคลากร (ได้รับจากท้องถิ่น) | N17: (3) ค่าจ้างครูและบุคลากร (ได้รับจากท้องถิ่น)
C18: (4) ค่าจ้างครูอัตราจ้างรายเดือน โดย เงินอื่นๆ (เช่นเงินอุดหนุนรายหัว เงินบำรุงการศึกษา เงินบริจาค และเงินรายได้สถานศึกษา เป็นต้น) | G18: =#REF! -> #REF! | N18: (4) ค่าจ้างครูอัตราจ้างรายเดือน โดย เงินอื่นๆ (เช่นเงินอุดหนุนรายหัว เงินบำรุงการศึกษา เงินบริจาค และเงินรายได้สถานศึกษา เป็นต้น) | R18: =#REF! -> #REF!
C19: (5) ค่าจ้างธุรการโครงการคืนครูให้นักเรียน [ส่วนที่ 3 ข้อ 2.4(2)] | D19: 0 | N19: (5) ค่าจ้างธุรการโครงการคืนครูให้นักเรียน [ส่วนที่ 3 ข้อ 2.4(2)] | O19: 0
C20: (6) ค่าจ้างเจ้าหน้าที่ประจำห้องปฏิบัติการ [ส่วนที่ 3 ข้อ 2.4(3)] | D20: 0 | N20: (6) ค่าจ้างเจ้าหน้าที่ประจำห้องปฏิบัติการ [ส่วนที่ 3 ข้อ 2.4(3)] | O20: 0
C21: (7) ค่าจ้างพี่เลี้ยงเด็กพิการ [ส่วนที่ 3 ข้อ 2.4(4)] | D21: 0 | N21: (7) ค่าจ้างพี่เลี้ยงเด็กพิการ [ส่วนที่ 3 ข้อ 2.4(4)] | O21: 0
C22: (8) ค่าตอบแทนวิทยากรบุคคลภายนอกรายชั่วโมง (ยกเว้นค่าตอบแทนวิทยากรผู้สอนศาสนาอิสลาม) | N22: (8) ค่าตอบแทนวิทยากรบุคคลภายนอกรายชั่วโมง (ยกเว้นค่าตอบแทนวิทยากรผู้สอนศาสนาอิสลาม)
C23: (9) ค่าจ้างบุคลากรอื่นๆ (บรรณารักษ์ , พยาบาล, แม่บ้าน, แม่ครัว,ทำความสะอาด คนงานดูแลสวน , ดูแลหอพัก ฯลฯ ) | N23: (9) ค่าจ้างบุคลากรอื่นๆ (บรรณารักษ์ , พยาบาล, แม่บ้าน, แม่ครัว,ทำความสะอาด คนงานดูแลสวน , ดูแลหอพัก ฯลฯ )
C24: (10) ค่าตอบแทนพิเศษเงินเดือนเต็มขั้น [ส่วนที่ 3 ข้อ 2.4(5)] | D24: 0 | N24: (10) ค่าตอบแทนพิเศษเงินเดือนเต็มขั้น [ส่วนที่ 3 ข้อ 2.4(5)] | O24: 0
C25: (11) ค่าตอบแทนวิทยากร/ครูผู้สอนศาสนาอิสลาม [ส่วนที่ 3 ข้อ 2.4(6)] | D25: 0 | N25: (11) ค่าตอบแทนวิทยากร/ครูผู้สอนศาสนาอิสลาม [ส่วนที่ 3 ข้อ 2.4(6)] | O25: 0
C26: (12) ค่าตอบแทนพิเศษรายเดือนสำหรับข้าราชการ พนักงานราชการและลูกจ้างที่ปฏิบัติหน้าที่ในพื้นที่พิเศษ [ส่วนที่ 3 ข้อ 2.4(7)] | D26: 0 | N26: (12) ค่าตอบแทนพิเศษรายเดือนสำหรับข้าราชการ พนักงานราชการและลูกจ้างที่ปฏิบัติหน้าที่ในพื้นที่พิเศษ [ส่วนที่ 3 ข้อ 2.4(7)] | O26: 0
C27: (13) เงินสมทบกองทุนประกันสังคม (เช่น สพฐ. สพป. สพม. โรงเรียน อปท. เป็นต้น) [ส่วนที่ 3 ข้อ 2.4(8)] | D27: 0 | N27: (13) เงินสมทบกองทุนประกันสังคม (เช่น สพฐ. สพป. สพม. โรงเรียน อปท. เป็นต้น) [ส่วนที่ 3 ข้อ 2.4(8)] | O27: 0
C28: (14) ค่าเช่าบ้าน [ส่วนที่ 3 ข้อ 2.4(9)] | D28: 0 | N28: (14) ค่าเช่าบ้าน [ส่วนที่ 3 ข้อ 2.4(9)] | O28: 0
B29: 2.2 | C29: โครงการพัฒนาบุคลากรตามแผนปฏิบัติการประจำปี | M29: 2.2 | N29: โครงการพัฒนาบุคลากรตามแผนปฏิบัติการประจำปี
B30: 2.3 | C30: อื่น ๆ | M30: 2.3 | N30: อื่น ๆ
A31: 3. | B31: ด้านการบริหารงบประมาณ | D31: 0 | E31: 0 | F31: 0 | G31: 0 | H31: 0 | I31: 0 | L31: 3. | M31: ด้านการบริหารงบประมาณ | O31: 0 | P31: 0 | Q31: 0 | R31: 0 | S31: 0 | T31: 0
B32: 3.1 | C32: ค่าครุภัณฑ์ | M32: 3.1 | N32: ค่าครุภัณฑ์ | P32: =#REF! -> #REF!
B33: 3.2 | C33: ค่าซ่อมแซมครุภัณฑ์ | E33: =#REF! -> #REF! | M33: 3.2 | N33: ค่าซ่อมแซมครุภัณฑ์ | P33: =#REF! -> #REF!
B34: 3.3 | C34: ค่าก่อสร้างอาคารเรียน อาคารประกอบและสิ่งก่อสร้างอื่น | M34: 3.3 | N34: ค่าก่อสร้างอาคารเรียน อาคารประกอบและสิ่งก่อสร้างอื่น
B35: 3.4 | C35: ค่าปรับปรุง/ขยายเขตระบบไฟฟ้า ประปา | M35: 3.4 | N35: ค่าปรับปรุง/ขยายเขตระบบไฟฟ้า ประปา | P35: =#REF! -> #REF!
B36: 3.5 | C36: ค่าปรับปรุงซ่อมแซมอาคารเรียน อาคารประกอบ และสิ่งก่อสร้างอื่น | E36: =#REF! -> #REF! | M36: 3.5 | N36: ค่าปรับปรุงซ่อมแซมอาคารเรียน อาคารประกอบ และสิ่งก่อสร้างอื่น | P36: =#REF! -> #REF!
B37: 3.6 | C37: เงินเหลือจ่ายจากการก่อหนี้ผูกพัน | M37: 3.6 | N37: เงินเหลือจ่ายจากการก่อหนี้ผูกพัน
B38: 3.7 | C38: โครงการการบริหารงบประมาณตามแผนปฏิบัติการประจำปี | E38: =#REF! -> #REF! | M38: 3.7 | N38: โครงการการบริหารงบประมาณตามแผนปฏิบัติการประจำปี | P38: =#REF! -> #REF!
B39: 3.8 | C39: อื่น ๆ (เช่น ค่ากำจัดปลวก เป็นต้น) | M39: 3.8 | N39: อื่น ๆ (เช่น ค่ากำจัดปลวก เป็นต้น)
A40: 4. | B40: ด้านการบริหารทั่วไป | D40: 0 | E40: 0 | F40: 0 | G40: 0 | H40: 0 | I40: 0 | L40: 4. | M40: ด้านการบริหารทั่วไป | O40: 0 | P40: 0 | Q40: 0 | R40: 0 | S40: 0 | T40: 0
...

Sheet เงินลูกเสือ
A1: ผอ. | B1: ตลอดชีพ
A2: แก้ว | B2: ตลอดชีพ
A3: กาญ | B3: ตลอดชีพ
A4: สรคม | B4: ตลอดชีพ
A5: ส้ม | B5: ตลอดชีพ
A6: ใหม่ | B6: ตลอดชีพ
A7: แจ๊ก | B7: ตลอดชีพ
A8: ภาม | B8: รายปี
A9: เดียร์ | B9: รายปี
A10: ตง | B10: รายปี
A11: หน่อย | B11: รายปี
A12: นิค | B12: รายปี
... A14: ตุ๊ก | B14: รายปี
A20: ประเภท | B20: อัตราจัดเก็บ | C20: จำนวนคน(1) | D20: หักค่าบำรุงลูกเสือโลก(2) | E20: เงินที่เก็บไว้ที่กองลูกเสือ | G20: คงเหลือนำส่ง(4) | H20: เงินที่นำส่งทั้งสิ้น
E21: อัตราต่อคน(3) | F21: รวมจำนวนเงิน(1)x(3) | H21: อัตราต่อคน(2)+(4) | K21: จัดเก็บทั้งหมด | L21: ตรวจสอบ
A22: ลูกเสือ | B22: 5 | C22: 172 | D22: =C22*0.5 -> 86 | E22: 3.15 | F22: =C22*E22 -> 541.8 | G22: =C22*1.35 -> 232.2 | H22: =C22*1.85 -> 318.2 | K22: =B22*C22 -> 860 | L22: =F22+H22 -> 860
A23: ผบ.ลูกเสือ | K23: =B23*C23 -> 0 | L23: =F23+H23 -> 0
A24: รายปี | B24: 30 | C24: 7 | D24: 0 | E24: 0 | F24: 0 | G24: 0 | H24: =C24*B24 -> 210 | K24: =B24*C24 -> 210 | L24: =F24+H24 -> 210
A25: ตลอดชีพ | B25: 300 | C25: 0 | D25: 0 | E25: 0 | F25: 0 | G25: 0 | H25: =C25*B25 -> 0 | K25: =B25*C25 -> 0 | L25: =F25+H25 -> 0
A26: เจ้าหน้าที่ลูกเสือ/บุคลากรทางการลูกเสือ(ตลอดชีพ) | B26: 300 | C26: 0 | D26: 0 | E26: 0 | F26: 0 | G26: 0 | H26: =C26*B26 -> 0 | K26: =B26*C26 -> 0 | L26: =F26+H26 -> 0
A27: รวมทั้งสิ้น | B27: - | C27: =SUM(C22:C26) -> 179 | D27: =SUM(D22:D26) -> 86 | E27: - | F27: =SUM(F22:F26) -> 541.8 | G27: =SUM(G22:G26) -> 232.2 | H27: =SUM(H22:H26) -> 528.2 | J27: รวม | K27: =SUM(K22:K26) -> 1070 | L27: =F27+H27 -> 1070
